Workbook
Name Harga_Biosolar: '⚙️ Parameter Global'!$C$16
Name Harga_Pertalite: '⚙️ Parameter Global'!$C$17
Name HariKerja_PerBulan: '⚙️ Parameter Global'!$C$7
Name JamKerja_PerBulan: '⚙️ Parameter Global'!$C$9
Name JamKerja_PerHari: '⚙️ Parameter Global'!$C$8
Name Kecepatan_Kendaraan: '⚙️ Parameter Global'!$C$10

Sheet ⚙️ Parameter Global
B1: ⚙️ PARAMETER GLOBAL — Single source of truth
B3: Semua parameter di bawah ini dipake oleh sheet lain via cell reference. Ubah di sini, semuanya ikut update.
B5: 🧑‍💼 HUMAN-CENTRIC PARAMETERS (Batasan Jam Kerja Manusia)
B6: Parameter | C6: Nilai | D6: Satuan | E6: Penjelasan
B7: Hari kerja per bulan | C7: 26 | D7: hari | E7: Asumsi: 6 hari/minggu × ~4,33 minggu/bulan
B8: Jam kerja per hari | C8: 8 | D8: jam | E8: Standar UU Ketenagakerjaan No. 13/2003
B9: Total jam kerja/bulan | C9: =C7*C8 -> 208 | D9: jam | E9: Cap maksimum waktu driver per bulan
B10: Kecepatan rata-rata kendaraan | C10: 45 | D10: km/jam | E10: Asumsi kecepatan truk darat rata-rata
B12: 💡 Formula T_k (Trip Max per Kendaraan) = FLOOR(JamKerja_PerBulan / (Jarak_terjauh / Kecepatan), 1)
B14: ⛽ HARGA BBM
B15: Jenis BBM | C15: Harga | D15: Satuan | E15: Dipake oleh
B16: Biosolar (Solar Subsidi) | C16: 6800 | D16: Rp/Liter | E16: CDD, CDE
B17: Pertalite | C17: 10000 | D17: Rp/Liter | E17: GrandMax, Kijang, Motorbike
B19: 🚛 KAPASITAS & KONSUMSI KENDARAAN
B20: Jenis Kendaraan | C20: Kapasitas (boks) | D20: Konsumsi BBM | E20: Jenis BBM
B21: CDD | C21: 280 | D21: 4 | E21: Biosolar
B22: CDE | C22: 200 | D22: 7 | E22: Biosolar
B23: GrandMax | C23: 120 | D23: 8 | E23: Pertalite
B24: Kijang | C24: 80 | D24: 10 | E24: Pertalite
B25: Motorbike | C25: 5 | D25: 15 | E25: Pertalite
B27: 📦 KAPASITAS KONTAINER (First Mile)
B28: Jenis Kontainer | C28: Volume (boks) | D28: Volume (m³) | E28: Catatan
B29: 40FT | C29: 2360 | D29: 67 | E29: Kontainer laut besar
B30: Build Up | C30: 1600 | E30: Kontainer reefer/khusus
B31: 20FT | C31: 1160 | D31: 33 | E31: Kontainer laut kecil
B32: FUSO | C32: 880 | E32: Truk berat
B33: CDD | C33: 280 | D33: 25 | E33: Truk medium (juga di middle mile)

Sheet 📘 Model Matematis
B1: 📘 MODEL MATEMATIS — Minimisasi Biaya Transportasi FMCG
B2: Wilayah Kalimantan, Sulawesi, BaliNusra · MILP (Mixed Integer Linear Programming)
B4: 🚢 MODEL 1: FIRST MILE (Pabrik Karawang → Direct CPU / Direct DC)
B5: Output: total biaya transportasi first mile per bulan (Rp)
B7: INDEKS
B8: i | C8: Lokasi asal: BaliNusra, Sulawesi, Kalimantan
B9: j | C9: Lokasi tujuan: 15 DC (Direct CPU + Direct DC)
B10: v | C10: Jenis container: 40FT, Build Up, 20FT, FUSO, CDD
B12: VARIABEL KEPUTUSAN
B13: x_ijv | C13: Jumlah trip container v dari lokasi i ke j (integer ≥ 0)
B14: b_ijv | C14: Biner: 1 jika container v dipake untuk rute i→j
B15: q_ijv | C15: Jumlah boks dikirim dari i ke j dengan container v (≥ 0)
B17: FUNGSI OBJEKTIF
B18: Min Z₁ = ΣᵢΣⱼΣᵥ r_ijv × b_ijv × x_ijv
B19: r_ijv = Rate T&W (Rp/trip), dari sheet "Rate T&W"
B21: FUNGSI PEMBATAS (Constraint)
B22: 1 | C22: q_ijv ≤ C_v × x_ijv | D22: Jumlah boks ≤ kapasitas container × jumlah trip
B23: 2 | C23: Σ q_ijv ≥ D_j | D23: Total kiriman ≥ demand bulanan di tujuan j
B24: 3 | C24: q_ijv ≥ 0 | D24: Jumlah boks non-negatif
B25: 4 | C25: x_ijv ≥ 0, integer | D25: Jumlah trip non-negatif & bulat
B28: 🚚 MODEL 2: MIDDLE MILE (Direct CPU/DC → Indirect DC / Depo)
B29: Output: total biaya transportasi middle mile per bulan (Rp) · BBM + Driver + Staff + Sewa Kendaraan
B31: INDEKS
B32: k | C32: Lokasi asal: 27 hub (9 Direct DC + 6 Direct CPU + 12 Indirect DC)
B33: l | C33: Lokasi tujuan: 42 (12 Indirect DC + 30 Depo/Machine Room)
B34: m | C34: Jenis kendaraan: CDD, CDE, GrandMax, Kijang, Motorbike
B36: VARIABEL KEPUTUSAN
B37: x_klm | C37: Jumlah trip kendaraan m dari k ke l (integer ≥ 0)
B38: n_klm | C38: Jumlah unit kendaraan m yang dipake di rute k→l
B39: b_klm | C39: Biner: 1 jika kendaraan m dipake
B40: q_klm | C40: Jumlah boks dikirim (≥ 0)
B42: FUNGSI OBJEKTIF (4 komponen biaya)
B43: Min Z₂ = Σ(r_klm × b_klm × n_klm) ← Sewa kendaraan + Σ((2 × d_kl × c_m / p_m) × x_klm) ← BBM (×2 untuk PP) + 2 × Σ(s_kl × n_klm) ← Driver + f_kl ← Staff gudang
B44: r_klm = tarif sewa kendaraan · d_kl = jarak · c_m = harga BBM · p_m = konsumsi BBM (km/L) · s_kl = biaya driver · f_kl = biaya staff
B46: FUNGSI PEMBATAS (Constraint)
B47: 1 | C47: q_klm ≤ C_m × x_klm | D47: Boks ≤ kapasitas kendaraan × trip
B48: 2 | C48: Σ q_klm ≥ D_l | D48: Demand di tujuan l terpenuhi
B49: 3 | C49: q_lm × x_lm ≤ G_k | D49: Total kirim 1 batch ≤ kapasitas gudang asal k
B50: 4 | C50: q_klm ≥ 0 | D50: Boks non-negatif
B51: 5 | C51: x_klm ≥ 0, integer | D51: Trip non-negatif & bulat
...

Sheet ✅ Verifikasi vs Gurobi
B1: ✅ VERIFIKASI DATA vs GUROBI CODE
B2: Cek konsistensi data mastersheet dengan Gurobi code (rujukan mutlak)
B4: 📊 RINGKASAN
B5: Item Diverifikasi | C5: Status | F5: Detail
B6: MaxTrip per asal (14 area) | C6: ✓ MATCH | F6: ✓ Semua match. Dihitung dari T_k = 208 ÷ (jarak terjauh / 45 km/jam)
B7: Sewa kendaraan rate (Kalimantan tier) | C7: ✓ MATCH | F7: ✓ CDD 13.85M, CDE/GM/Kijang 6.56M — match
B8: Sewa kendaraan rate (Sulawesi/BaliNusra tier) | C8: ✓ MATCH | F8: ✓ CDD 6.9M, CDE 5.5M, GM 3.5M — match
B9: BBM rate per (asal,kendaraan,tujuan) | C9: ✓ MATCH | F9: ✓ Sample verified (Lombok block, Banjarmasin block) — match
B10: Middle Mile demand per route | C10: ✓ MATCH | F10: ✓ Total kirim per route memenuhi demand Gurobi
B11: First Mile demand (di sheet Sulawesi/Kalimantan/BaliNusra) | C11: ✓ MATCH | F11: ✓ Itu LOCAL DEMAND (bukan throughput). Both correct, beda metric.
B12: First Mile demand (di sheet Total Biaya First Mile) | C12: ✓ MATCH | F12: ✓ FIXED v5: pisahin Local Demand + Forward + Throughput. Cost pake throughput.
B15: 📋 DETAIL DEMAND FIRST MILE — Laporan vs Gurobi
B16: Area | C16: Local Demand (Laporan) | D16: Throughput (Gurobi FM) | E16: Forward (Selisih) | F16: Status
B17: Denpasar | C17: 28496 | D17: 28496 | E17: 0 | F17: ✓ Tidak ada forward
B18: Lombok | C18: 17216 | D18: 37767 | E18: 20551 | F18: Forward 20,551 boks ke Indirect/Depo
B19: Kendari | C19: 6252 | D19: 14736 | E19: 8484 | F19: Forward 8,484 boks ke Indirect/Depo
B20: Makassar | C20: 8800 | D20: 62670 | E20: 53870 | F20: Forward 53,870 boks ke Indirect/Depo
B21: Manado | C21: 6680 | D21: 25418 | E21: 18738 | F21: Forward 18,738 boks ke Indirect/Depo
B22: Palu | C22: 7491 | D22: 23275 | E22: 15784 | F22: Forward 15,784 boks ke Indirect/Depo
B23: Balikpapan | C23: 16518 | D23: 21193 | E23: 4675 | F23: Forward 4,675 boks ke Indirect/Depo
B24: Banjarmasin | C24: 22620 | D24: 47169 | E24: 24549 | F24: Forward 24,549 boks ke Indirect/Depo
B25: Berau | C25: 2879 | D25: 2879 | E25: 0 | F25: ✓ Tidak ada forward
B26: Bontang | C26: 2010 | D26: 3340 | E26: 1330 | F26: Forward 1,330 boks ke Indirect/Depo
B27: Palangkaraya | C27: 4632 | D27: 9255 | E27: 4623 | F27: Forward 4,623 boks ke Indirect/Depo
B28: Pontianak | C28: 8377 | D28: 18499 | E28: 10122 | F28: Forward 10,122 boks ke Indirect/Depo
... B31: Tarakan | C31: 12523 | D31: 12523 | E31: 0 | F31: ✓ Tidak ada forward
B34: 💰 EXPECTED OPTIMAL COSTS
B35: Komponen | C35: Nilai (Rp/bulan) | F35: Catatan
B36: First Mile (Z₁ optimal) | C36: 2969314226 | F36: Mix optimal container, demand Gurobi
B37: Middle Mile BBM (per Gurobi solution) | C37: 236013211 | F37: Match existing sheet — sudah benar
B38: Middle Mile Driver | C38: 396377594 | F38: Match existing sheet — sudah benar
B39: Middle Mile Sewa Kendaraan | C39: 251018432 | F39: Total dari summary 4-komponen v3
B40: Middle Mile Staff | C40: 392936204 | F40: Total dari summary 4-komponen v3
B41: GRAND TOTAL Z₁ + Z₂ per bulan | C41: 4245659667 | F41: ~ Rp 4.25 Miliar/bulan

Sheet Penjelasan Gurobi (Kode)
B1: 🐍 IMPLEMENTASI GUROBI — Penjelasan + Kode Python
B2: Kode optimasi MILP untuk Model 2 (Middle Mile). Untuk notasi matematis lihat sheet 📘 Model Matematis.
B3: Penjelasan | C3: Kode Python
B4: 🎯 Tujuan Model
B5: Mengoptimalkan pengiriman barang dengan meminimalkan total biaya yang terdiri dari: • Biaya BBM — tergantung jarak & konsumsi bahan bakar • Biaya penambahan kendaraan — biaya tetap saat menyewa kendaraan baru | C5: import gurobipy as gp from gurobipy import GRB import pandas as pd m = gp.Model("MiddleMileOptimization")
B6: 📥 Bagian 1: Input Data
B7: Data tujuan: ID, Kota, Jarak, Demand untuk tiap lokasi tujuan. | C7: tujuan_data = { 'ID_Tujuan': ['DC009','DC010','DC011','DC018','DC027','DC048','DC054','DC055'], 'Kota': ['Bulukumba','Gowa','Jeneponto','Pangkep','Takalar','Bone','Palopo','Pare-Pare'], 'Jarak': [200, 16.37, 97.42, 55.23, 41.33, 194.85, 375.38, 162.64], 'Demand': [2549, 11369, 2561, 1826, 1978, 2871, 3259, 5309] } tujuan = pd.DataFrame(tujuan_data)
B8: Data kendaraan: Type, Volume (kapasitas), BBM (jenis bahan bakar), Cons (konsumsi km/liter). | C8: kendaraan_data = { 'Type': ['CDD', 'CDE', 'GrandMax'], 'Volume': [280, 200, 120], 'BBM': ['biosolar', 'biosolar', 'pertalite'], 'Cons': [4, 7, 8] } kendaraan = pd.DataFrame(kendaraan_data) harga_bbm = {'biosolar': 6800, 'pertalite': 10000}
B9: 🎲 Bagian 2: Variabel Keputusan
B10: x[k,j,t]: biner → kendaraan k mengirim ke tujuan j pada trip ke-t y[k,j,t]: integer → jumlah boks yang dikirim kendaraan k ke j pada trip t z[k,i]: biner → apakah kendaraan jenis k unit ke-i dipakai | C10: x = m.addVars(..., vtype=GRB.BINARY, name="x") y = m.addVars(..., vtype=GRB.INTEGER, name="y") z = m.addVars(..., vtype=GRB.BINARY, name="z")
B11: 🎯 Bagian 3: Fungsi Tujuan (Objective)
B12: Minimasi total biaya = Biaya BBM + Biaya penambahan kendaraan. BIAYA BBM per trip: = 2 × (Jarak / Konsumsi) × Harga BBM Faktor 2 untuk perjalanan PULANG-PERGI. | C12: obj = gp.LinExpr() # Biaya BBM for k_row in kendaraan.itertuples(): for j_row in tujuan.itertuples(): for t in range(MAX_TRIPS): jarak = j_row.Jarak konsumsi = k_row.Cons bbm = harga_bbm[k_row.BBM] biaya_per_trip = 2*(jarak/konsumsi)*bbm # 2x PP obj += biaya_per_trip * x[(k_row.Type, j_row.ID_Tujuan, t)] # Biaya penambahan kendaraan for k_row in kendaraan.itertuples(): for i in range(1, 20): obj += biaya_kendaraan[k_row.Type] * z[(k_row.Type, i)] m.setObjective(obj, GRB.MINIMIZE)
B13: ⛔ Bagian 4: Pembatasan (Constraints)
B14: (a) DEMAND HARUS TERPENUHI Total boks yang dikirim ke tujuan j selama seluruh trip ≥ demand di j. | C14: for j_row in tujuan.itertuples(): m.addConstr( gp.quicksum(y[(k.Type, j_row.ID_Tujuan, t)] for k in kendaraan.itertuples() for t in range(MAX_TRIPS)) >= j_row.Demand, name=f"demand_{j_row.ID_Tujuan}" )
B15: (b) KAPASITAS KENDARAAN Boks yang dikirim ≤ kapasitas kendaraan × jumlah trip. | C15: for k_row in kendaraan.itertuples(): for j in tujuan['ID_Tujuan']: for t in range(MAX_TRIPS): m.addConstr( y[(k_row.Type, j, t)] <= kendaraan.loc[k_row.Index,'Volume'] * x[(k_row.Type, j, t)], name=f"kapasitas_{k_row.Type}_{j}_trip{t}" )
B16: (c) KAPASITAS GUDANG PER TRIP Total boks dalam satu trip ≤ kapasitas gudang asal. | C16: for t in range(MAX_TRIPS): m.addConstr( gp.quicksum(y[(k.Type, j, t)] for k in kendaraan.itertuples() for j in tujuan['ID_Tujuan']) <= 2920, # contoh: kap. gudang Makassar name=f"gudang_trip{t}" )
B17: (d) AKTIVASI KENDARAAN x[k,j,t] hanya aktif kalau ada kendaraan jenis k yang dipakai (z=1). | C17: for k in kendaraan['Type']: for j in tujuan['ID_Tujuan']: for t in range(MAX_TRIPS): m.addConstr( x[(k, j, t)] <= gp.quicksum(z[(k, i)] for i in range(1, 20)), name=f"use_vehicle_{k}_{j}_trip{t}" )
B18: (e) 🧑‍💼 HUMAN-CENTRIC — PEMBATAS JUMLAH TRIP Setiap kendaraan max 26 trip per bulan. Detail rumus T_k lihat sheet "Jumlah Trip Maksimal". Filosofi: jam kerja driver dibatasi 26 hari × 8 jam = 208 jam/bulan. | C18: for k in kendaraan['Type']: for i in range(1, 20): for t in range(MAX_TRIPS): m.addConstr( gp.quicksum(x[(k, j, t)] for j in tujuan['ID_Tujuan']) <= 26 * z[(k, i)], name=f"max_trips_{k}_v{i}_t{t}" )
B19: ✅ Bagian 5: Penyelesaian (Solve)
B20: Jalankan solver Gurobi dan ekstrak hasil: • Total biaya minimum (Z₂) • Daftar rute (kendaraan → tujuan → trip) • Jumlah kendaraan per jenis yang dipakai | C20: m.optimize() if m.status == GRB.OPTIMAL: print("Total Biaya:", m.ObjVal) for k, j, t in x: if x[(k, j, t)].X > 0.5: print(f"Kendaraan {k} kirim {int(y[(k,j,t)].X)} boks ke {j} trip-{t+1}") kendaraan_digunakan = {} for k_row in kendaraan.itertuples(): for i in range(1, 20): if z[(k_row.Type, i)].X > 0.5: kendaraan_digunakan[k_row.Type] = kendaraan_digunakan.get(k_row.Type, 0) + 1 for tipe, count in kendaraan_digunakan.items(): print(f"{tipe}: {count} kendaraan")

Sheet 🐍 Kode First Mile
A1: 🐍 KODE GUROBI — FIRST MILE (Karawang → Direct CPU/DC)
A2: Source: Kode_Guroby-Phyton_FirstMile.pdf — 2 blok: Sulawesi/Kalimantan dan BaliNusra
A4: 📦 BLOK 1: First Mile Sulawesi & Kalimantan
A5: 1 | B5: # ============================================================
A6: 2 | B6: # KODE FIRST MILE — Sulawesi dan Kalimantan
A7: 3 | B7: # ============================================================
A8: 4 | B8: import gurobipy as gp
A9: 5 | B9: from gurobipy import Model, GRB, quicksum
A10: 6 | B10: import pandas as pd
A11: 7 | B11: import math
A12: 8
A13: 9 | B13: # --- 1. Data Permintaan (THROUGHPUT = local + forward via Middle Mile) ---
A14: 10 | B14: df_demand = pd.DataFrame([
A15: 11 | B15: ['Kendari', 'DC032', 'Direct CPU', 14736],
A16: 12 | B16: ['Makassar', 'DC034', 'Direct CPU', 62670],
A17: 13 | B17: ['Manado', 'DC035', 'Direct CPU', 25418],
A18: 14 | B18: ['Palu', 'DC036', 'Direct CPU', 23275],
A19: 15 | B19: ['Balikpapan', 'DC037', 'Direct DC', 21193],
A20: 16 | B20: ['Banjarmasin', 'DC038', 'Direct DC', 47169],
A21: 17 | B21: ['Berau', 'DC039', 'Direct DC', 2879],
A22: 18 | B22: ['Bontang', 'DC040', 'Direct DC', 3340],
A23: 19 | B23: ['Palangkaraya', 'DC041', 'Direct DC', 9255],
A24: 20 | B24: ['Pontianak', 'DC042', 'Direct DC', 18499],
... A28: 24 | B28: ], columns=['Area', 'ID', 'Type', 'Demand'])
A29: 25
A30: 26 | B30: # --- 2. Data Kapasitas Kontainer ---
A31: 27 | B31: df_kapasitas = pd.DataFrame([
A32: 28 | B32: ['40FT', 2360],
A33: 29 | B33: ['Build Up', 1600],
A34: 30 | B34: ['20FT', 1160],
A35: 31 | B35: ['FUSO', 880],
A36: 32 | B36: ['CDD', 280],
A37: 33 | B37: ], columns=['Type', 'Volume'])
A38: 34
A39: 35 | B39: # --- 3. Data Biaya (Rate T&W) ---
A40: 36 | B40: df_biaya = pd.DataFrame([
A41: 37 | B41: ['Sulawesi', 'DC034', 'Makassar', 'Direct CPU', '40FT', '17000000'],
A42: 38 | B42: ['Sulawesi', 'DC032', 'Kendari', 'Direct CPU', '40FT', '28460000'],
A43: 39 | B43: ['Sulawesi', 'DC032', 'Kendari', 'Direct CPU', '20FT', '17200000'],
A44: 40 | B44: ['Sulawesi', 'DC036', 'Palu', 'Direct CPU', '40FT', '17250000'],
...

Sheet 🐍 Kode Middle Mile
A1: 🐍 KODE GUROBI — MIDDLE MILE (Direct CPU/DC → Indirect DC/Depo)
A2: Source: KODE_MIDDLE_MILE.pdf — 14 blok per hub. Tiap blok = ILP terpisah per hub.
A4: 🚚 BLOK 1: Banjarmasin → Barabai, Batu Licin, Rantau (max trip/kendaraan: 46)
A5: 1 | B5: # ============================================================
A6: 2 | B6: # Middle Mile: Banjarmasin → Barabai, Batu Licin, Rantau
A7: 3 | B7: # ============================================================
A8: 4 | B8: import gurobipy as gp
A9: 5 | B9: from gurobipy import Model, GRB, quicksum
A10: 6
A11: 7 | B11: # --- Data ---
A12: 8 | B12: kendaraan = ['CDD', 'CDE', 'GrandMax', 'Kijang']
A13: 9 | B13: daerah = ['Barabai', 'Batu Licin', 'Rantau']
A14: 10 | B14: jarak = {'Barabai': 1046.393, 'Batu Licin': 924.619, 'Rantau': 179.485}
A15: 11
A16: 12 | B16: biaya_bbm = {
A17: 13 | B17: 'CDD': {'Barabai': 246238.2, 'Batu Licin': 345288.7, 'Rantau': 160248.8},
A18: 14 | B18: 'CDE': {'Barabai': 140707.5429, 'Batu Licin': 197307.8286, 'Rantau': 91570.74286},
A19: 15 | B19: 'GrandMax': {'Barabai': 181057.5, 'Batu Licin': 253888.75, 'Rantau': 117830},
A20: 16 | B20: 'Kijang': {'Barabai': 144846, 'Batu Licin': 203111, 'Rantau': 94264},
A21: 17 | B21: }
A22: 18
A23: 19 | B23: biaya_kendaraan = {'CDD': 13853970, 'CDE': 6560843.333, 'GrandMax': 6560843.333, 'Kijang': 6560843.333}
A24: 20 | B24: kapasitas_kendaraan = {'CDD': 280, 'CDE': 200, 'GrandMax': 120, 'Kijang': 80}
A25: 21 | B25: demand = {'Barabai': 12496, 'Batu Licin': 7766, 'Rantau': 4287}
A26: 22 | B26: kapasitas_max_per_trip = 5280
A27: 23 | B27: MAX_TRIP_PER_VEHICLE = 46 # 🧑‍💼 HUMAN-CENTRIC constraint
A28: 24
A29: 25 | B29: # --- Model ---
A30: 26 | B30: m = Model("Vehicle_Optimization")
A31: 27
A32: 28 | B32: # Variabel keputusan
A33: 29 | B33: x = m.addVars(kendaraan, daerah, vtype=GRB.INTEGER, name="Vehicles") # jumlah kendaraan
A34: 30 | B34: t = m.addVars(kendaraan, daerah, vtype=GRB.INTEGER, name="Trips") # jumlah trip
A35: 31 | B35: muatan = m.addVars(kendaraan, daerah, vtype=GRB.CONTINUOUS, name="Load") # boks dikirim
A36: 32
A37: 33 | B37: # Fungsi objektif: BBM (×2 PP) + Sewa kendaraan
A38: 34 | B38: m.setObjective(quicksum(
A39: 35 | B39: biaya_bbm[k][d] * t[k, d] * 2 + biaya_kendaraan[k] * x[k, d]
A40: 36 | B40: for k in kendaraan for d in daerah
A41: 37 | B41: ), GRB.MINIMIZE)
...

Sheet Volume Container
B3: Type | C3: Volume | D3: m^3 | E3: Container (m) | F3: Gudang (m)
B4: 40FT | C4: 2360 | D4: 67 | E4: =D4^(1/3) -> 4.0615481 | F4: =SQRT(50000) -> 223.6068
B5: Build Up | C5: 1600
B6: 20FT | C6: 1160 | D6: 33
B7: FUSO | C7: 880
B8: CDD | C8: 280 | D8: 25
C10: 4623

Sheet Sulawesi
B3: Sulawesi | F3: 28495.968 | G3: Denpasar | H3: DC031 | I3: Direct CPU
B4: Wilayah | C4: Rerata Jarak | D4: Rerata Permintaan (boks/bulan) | F4: 6252 | G4: Kendari | H4: DC032 | I4: Direct CPU
B5: Amurang | C5: 18.071 | D5: 1729 | F5: 17215.408 | G5: Lombok | H5: DC033 | I5: Direct CPU
B6: Barru | C6: 10.64 | D6: 967 | F6: 8800 | G6: Makassar | H6: DC034 | I6: Direct CPU
B7: Bau-Bau | C7: 6.173 | D7: 2724 | F7: 6680 | G7: Manado | H7: DC035 | I7: Direct CPU
B8: Belopa | C8: 15.274 | D8: 1924 | F8: 7491 | G8: Palu | H8: DC036 | I8: Direct CPU
B9: Bitung | C9: 5.865 | D9: 2269
B10: Bone | C10: 15.975 | D10: 2871
B11: Bulukumba | C11: 26.986 | D11: 2549
B12: Gorontalo | C12: 14.201 | D12: 8017 | E12: =D12+D23 -> 10689
B13: Gowa | C13: 5.041 | D13: 11369
B14: Jeneponto | C14: 14.578 | D14: 2561
B15: Kendari | C15: 20.571 | D15: 6252 | E15: =D15+D7+D36+D16 -> 14736
B16: Kolaka | C16: 24.391 | D16: 3579
B17: Kotamobagu | C17: 8.049 | D17: 3692
B18: Luwuk | C18: 23.142 | D18: 9643
B19: Makassar | C19: 7.096 | D19: 8800 | E19: =D19+D11+D13+D14+D26+D32+D33+D10+D20+E24+E27 -> 62670
B20: Mamuju | C20: 16.957 | D20: 2902
B21: Manado | C21: 4.926 | D21: 6680 | E21: =D21+D9+D17+D34+E12 -> 25418
B22: Mangkutana | C22: 26.27 | D22: 4425
B23: Marisa | C23: 27.272 | D23: 2672
B24: Palopo | C24: 20.835 | D24: 3259 | E24: =D24+D8+D22+D35 -> 13393
B25: Palu | C25: 13.601 | D25: 7491 | E25: =D25+D30+D28+D18+D20 -> 23275
B26: Pangkep | C26: 8.625 | D26: 1826
B27: Pare-Pare | C27: 13.502 | D27: 5309 | E27: =D27+D6+D29+D31 -> 13252
B28: Parigi | C28: 20.277 | D28: 1223
B29: Polman | C29: 18.043 | D29: 3422
B30: Poso | C30: 20.928 | D30: 2016
B31: Sengkang | C31: 12.315 | D31: 3554
B32: Sinjai | C32: 10.669 | D32: 1169
B33: Takalar | C33: 5.803 | D33: 1978
B34: Tomohon | C34: 9.416 | D34: 2088
B35: Toraja | C35: 10.754 | D35: 3785
B36: Unaaha | C36: 23.65 | D36: 2181
B37: Grand Total | D37: =SUM(D4:D36) -> 124926

Sheet Kalimantan
B3: East Kalimantan(Customer POV)
B4: Wilayah | C4: Rerata Jarak | D4: Rerata Permintaan (boks/bulan)
B5: Ampah-Teweh | C5: 43.736 | D5: 4623
B6: Balikpapan | C6: 8.932 | D6: 16518 | E6: =D6+D16 -> 21193
B7: Banjarmasin | C7: 15.382 | D7: 22620 | E7: =D7+D8+D9+D17 -> 47169
B8: Barabai | C8: 31.066 | D8: 12496
B9: Batulicin | C9: 24.878 | D9: 7766
B10: Berau | C10: 38.022 | D10: 2879
B11: Bontang | C11: 3.592 | D11: 2010 | E11: =D11+D12 -> 3340
B12: Bontang-Sangata | C12: 3.514 | D12: 1330 | G12: 16518 | H12: Balikpapan | I12: DC037 | J12: Direct DC
B13: Ketapang | C13: 89.228 | D13: 208 | G13: 22620 | H13: Banjarmasin | I13: DC038 | J13: Direct DC
B14: Palangkaraya | C14: 9.204 | D14: 4632 | E14: =D14+D5 -> 9255 | G14: 2879 | H14: Berau | I14: DC039 | J14: Direct DC
B15: Pangkalanbun | C15: 8.186 | D15: 6285 | G15: 2010 | H15: Bontang | I15: DC040 | J15: Direct DC
B16: Penajam-Grogot | C16: 16.072 | D16: 4675 | G16: 4632 | H16: Palangkaraya | I16: DC041 | J16: Direct DC
B17: Rantau | C17: 13.288 | D17: 4287 | G17: 8377 | H17: Pontianak | I17: DC042 | J17: Direct DC
B18: Samarinda | C18: 9.821 | D18: 11295 | E18: =D18 -> 11295 | G18: 11295 | H18: Samarinda | I18: DC043 | J18: Direct DC
B19: Sampit | C19: 9.238 | D19: 4316 | E19: =D19+D15 -> 10601 | G19: 4316 | H19: Sampit | I19: DC044 | J19: Direct DC
B20: Sintang | C20: 301.356 | D20: 3 | G20: 12523 | H20: Tarakan | I20: DC045 | J20: Direct DC
B21: Tarakan | C21: 58.425 | D21: 12523 | E21: =D21 -> 12523
B22: West Kalimantan(Customer POV)
B23: Ketapang | C23: 73.283 | D23: 3105
B24: Pontianak | C24: 17.383 | D24: 8377 | E24: =D24+D25+D23+D26+D20+D13 -> 18499
B25: Singkawang | C25: 17.646 | D25: 3964
B26: Sintang | C26: 143.478 | D26: 2842
B27: Grand Total | D27: =SUM(D4:D26) -> 136754

Sheet BaliNusra
B3: BaliNusra
B4: Wilayah | C4: Rerata Jarak | D4: Rerata Permintaan (boks/bulan)
B5: BIMA | C5: 38.065991 | D5: =ROUNDUP(5782.422,0) -> 5783
B6: Denpasar | C6: 28.448189 | D6: =ROUNDUP(28495.968,0) -> 28496
B7: Kupang | C7: 58.323777 | D7: =ROUNDUP(8539.297,0) -> 8540
B8: Lombok | C8: 20.492709 | D8: =ROUNDUP(17215.408,0) -> 17216 | E8: =D8+D10+D5 -> 26518
B9: Maumere | C9: 30.513052 | D9: =ROUNDUP(2708.272,0) -> 2709
B10: Sumbawa | C10: 25.326844 | D10: =ROUNDUP(3518.842,0) -> 3519
B11: Grand Total | D11: =SUM(D5:D10) -> 66263
D27: =Sulawesi!D37+Kalimantan!D27+D11 -> 327943

Sheet Rate T&W
B3: Distributor Area | C3: ID | D3: Area | E3: Type | F3: Container | G3: Rate
B4: Bali Nusra | C4: DC031 | D4: Denpasar | E4: Direct CPU | F4: Build Up | G4: 12150000
B5: Bali Nusra | C5: DC031 | D5: Denpasar | E5: Direct CPU | F5: FUSO | G5: 8700000
B6: Bali Nusra | C6: DC033 | D6: Lombok | E6: Direct CPU | F6: Build Up | G6: 21440000
B7: Bali Nusra | C7: DC033 | D7: Lombok | E7: Direct CPU | F7: FUSO | G7: 16240000
B8: Bali Nusra | C8: DC033 | D8: Lombok | E8: Direct CPU | F8: CDD | G8: 12100000
B9: Sulawesi | C9: DC034 | D9: Makassar | E9: Direct CPU | F9: 40FT | G9: 17000000
B10: Sulawesi | C10: DC032 | D10: Kendari | E10: Direct CPU | F10: 40FT | G10: 28460000
B11: Sulawesi | C11: DC032 | D11: Kendari | E11: Direct CPU | F11: 20FT | G11: 17200000
B12: Sulawesi | C12: DC036 | D12: Palu | E12: Direct CPU | F12: 40FT | G12: 17250000
B13: Sulawesi | C13: DC036 | D13: Palu | E13: Direct CPU | F13: 20FT | G13: 10850000
B14: Sulawesi | C14: DC035 | D14: Manado | E14: Direct CPU | F14: 40FT | G14: 21900000
B15: Sulawesi | C15: DC035 | D15: Manado | E15: Direct CPU | F15: 20FT | G15: 13200000
... B30: Kalimantan | C30: DC045 | D30: Tarakan | E30: Direct DC | F30: 20FT | G30: 16174145

Sheet Total Biaya First Mile
B1: 💰 TOTAL BIAYA FIRST MILE — Karawang → Direct CPU / Direct DC
B2: Karawang ngirim cukup buat LOCAL + FORWARD ke Indirect DC/Depo. Jadi yang dikirim = THROUGHPUT bukan local demand doang.
B4: DC ID | C4: Area | D4: Type | E4: Local Demand | F4: Forward (Middle Mile) | G4: Throughput (=Local+Fwd) | H4: Mix Container Optimal | I4: Trips | J4: Total Biaya (Rp)
B5: DC031 | C5: Denpasar | D5: Direct CPU | E5: 28496 | F5: 0 | G5: 28496 | H5: 18× Build Up | I5: 18 | J5: 218700000
B6: DC033 | C6: Lombok | D6: Direct CPU | E6: 17216 | F6: 20551 | G6: 37767 | H6: 24× Build Up | I6: 24 | J6: 514560000
B7: DC032 | C7: Kendari | D7: Direct CPU | E7: 6252 | F7: 8484 | G7: 14736 | H7: 6× 40FT + 1× 20FT | I7: 7 | J7: 187960000
B8: DC034 | C8: Makassar | D8: Direct CPU | E8: 8800 | F8: 53870 | G8: 62670 | H8: 27× 40FT | I8: 27 | J8: 459000000
B9: DC035 | C9: Manado | D9: Direct CPU | E9: 6680 | F9: 18738 | G9: 25418 | H9: 11× 40FT | I9: 11 | J9: 240900000
B10: DC036 | C10: Palu | D10: Direct CPU | E10: 7491 | F10: 15784 | G10: 23275 | H10: 10× 40FT | I10: 10 | J10: 172500000
B11: DC037 | C11: Balikpapan | D11: Direct DC | E11: 16518 | F11: 4675 | G11: 21193 | H11: 9× 40FT | I11: 9 | J11: 1.6765984e+08
B12: DC038 | C12: Banjarmasin | D12: Direct DC | E12: 22620 | F12: 24549 | G12: 47169 | H12: 20× 40FT | I12: 20 | J12: 2.8678158e+08
B13: DC039 | C13: Berau | D13: Direct DC | E13: 2879 | F13: 0 | G13: 2879 | H13: 3× 20FT | I13: 3 | J13: 45217348
B14: DC040 | C14: Bontang | D14: Direct DC | E14: 2010 | F14: 1330 | G14: 3340 | H14: 3× 20FT | I14: 3 | J14: 53910446
B15: DC041 | C15: Palangkaraya | D15: Direct DC | E15: 4632 | F15: 4623 | G15: 9255 | H15: 4× 40FT | I15: 4 | J15: 91691106
B16: DC042 | C16: Pontianak | D16: Direct DC | E16: 8377 | F16: 10122 | G16: 18499 | H16: 8× 40FT | I16: 8 | J16: 1.3824391e+08
... B19: DC045 | C19: Tarakan | D19: Direct DC | E19: 12523 | F19: 0 | G19: 12523 | H19: 5× 40FT + 1× 20FT | I19: 6 | J19: 1.5683844e+08
B20: GRAND TOTAL FIRST MILE (Z₁ optimal, per bulan) | J20: =SUM(J5:J19) -> 2.9693142e+09
B22: 💡 PENJELASAN: Local Demand vs Throughput
B23: • LOCAL DEMAND (kolom E) = kebutuhan boks bulanan DC tersebut SAJA. Sumber: Tabel 3.8 Laporan.
B24: • FORWARD (kolom F) = boks yang DC ini akan terusin ke Indirect DC/Depo via Middle Mile.
B25: • THROUGHPUT (kolom G) = Local + Forward = total yang Karawang ngirim ke DC ini.
B26: • Biaya First Mile dihitung berdasar THROUGHPUT (kolom G), karena itu yang real dikirim.
B27: • Mix container OPTIMAL = solusi ILP per DC (minimize cost, satisfy throughput, capacity ≤ x×c).
B28: • Total per BULAN. Untuk per tahun, kalikan 12.

Sheet Biaya Variable KendaraanTrip ti
E1: Biaya BBM/Trip | I1: Rate(Biaya/Kapasitas Volume)/1 Perjalanan | N1: Biaya BBM | S1: Type | T1: Volume | U1: Harga BBM | V1: Petrol Consumption (Rasio BBM) | W1: Harga Bahan Bakar/KM
A2: Kepulauan | B2: Daerah Asal | C2: Tujuan | D2: Jarak | E2: {=TRANSPOSE(S2:S5)} -> CDD | F2: CDE | G2: GrandMax | H2: Kijang | I2: {=TRANSPOSE(S2:S5)} -> CDD | J2: CDE | K2: GrandMax | L2: Kijang | N2: Harga Solar | O2: 6800 | S2: CDD | T2: 280 | V2: 4 | W2: =6800/4 -> 1700 | Y2: Harga Solar | Z2: 6800
N3: Harga Pertalite | O3: 10000 | P3: Cek BBM TERENDAH | R3: Cek RATE Terendah | S3: CDE | T3: 200 | V3: 7 | W3: =6800/7 -> 971.42857 | Y3: Harga Pertalite | Z3: 10000
A4: Bali Nusra | B4: Lombok | C4: Kupang | D4: 1046.393 | E4: =$D$4/$V$2*6800 -> 1778868.1 | F4: =$D$4/$V$3*6800 -> 1016496.1 | G4: =$D$4/$V$4*10000 -> 1307991.2 | H4: =$D$4/$V$5*10000 -> 1046393 | I4: =E4/$T$2 -> 6353.1004 | J4: =F4/$T$3 -> 5082.4803 | K4: =G4/$T$4 -> 10899.927 | L4: =H4/$T$5 -> 13079.913 | P4: =MIN(E4:H4) -> 1016496.1 | Q4: CDE | R4: =MIN(I4:L4) -> 5082.4803 | S4: GrandMax | T4: 120 | V4: 8 | W4: =10000/4 -> 2500
C5: Maumere | D5: 924.619 | E5: =D5/$V$2*6800 -> 1571852.3 | F5: =D5/$V$3*6800 -> 898201.31 | G5: =D5/$V$4*10000 -> 1155773.8 | H5: =D5/$V$5*10000 -> 924619 | I5: =E5/$T$2 -> 5613.7582 | J5: =F5/$T$3 -> 4491.0066 | K5: =G5/$T$4 -> 9631.4479 | L5: =H5/$T$5 -> 11557.737 | P5: =MIN(E5:H5) -> 898201.31 | Q5: CDE | R5: =MIN(I5:L5) -> 4491.0066 | S5: Kijang | T5: 80 | V5: 10 | W5: =10000/10 -> 1000
C6: Sumbawa | D6: 179.485 | E6: =D6/$V$2*6800 -> 305124.5 | F6: =D6/$V$3*6800 -> 174356.86 | G6: =D6/$V$4*10000 -> 224356.25 | H6: =D6/$V$5*10000 -> 179485 | I6: =E6/$T$2 -> 1089.7304 | J6: =F6/$T$3 -> 871.78429 | K6: =G6/$T$4 -> 1869.6354 | L6: =H6/$T$5 -> 2243.5625 | P6: =MIN(E6:H6) -> 174356.86 | Q6: CDE | R6: =MIN(I6:L6) -> 871.78429 | S6: Motorbike | T6: 5 | V6: 15 | W6: =10000/15 -> 666.66667
D7: 440.971 | E7: =D7/$V$2*6800 -> 749650.7 | F7: =D7/$V$3*6800 -> 428371.83 | G7: =D7/$V$4*10000 -> 551213.75 | H7: =D7/$V$5*10000 -> 440971 | I7: =E7/$T$2 -> 2677.3239 | J7: =F7/$T$3 -> 2141.8591 | K7: =G7/$T$4 -> 4593.4479 | L7: =H7/$T$5 -> 5512.1375 | S7: https://drive.google.com/file/d/16zUUoSwMh_7Tqi-kTA__gdN4c5aFTCR9/view?usp=drive_link
A8: Kalimantan | B8: Balikpapan | C8: Penajam-Grogot | D8: 161.958 | E8: =D8/$V$2*6800 -> 275328.6 | F8: =D8/$V$3*6800 -> 157330.63 | G8: =D8/$V$4*10000 -> 202447.5 | H8: =D8/$V$5*10000 -> 161958 | I8: =E8/$T$2 -> 983.31643 | J8: =F8/$T$3 -> 786.65314 | K8: =G8/$T$4 -> 1687.0625 | L8: =H8/$T$5 -> 2024.475 | P8: =MIN(E8:H8) -> 157330.63 | Q8: CDE | R8: =MIN(I8:L8) -> 786.65314
A9: Kalimantan | B9: Banjarmasin | C9: Barabai | D9: 144.846 | E9: =D9/$V$2*6800 -> 246238.2 | F9: =D9/$V$3*6800 -> 140707.54 | G9: =D9/$V$4*10000 -> 181057.5 | H9: =D9/$V$5*10000 -> 144846 | I9: =E9/$T$2 -> 879.42214 | J9: =F9/$T$3 -> 703.53771 | K9: =G9/$T$4 -> 1508.8125 | L9: =H9/$T$5 -> 1810.575 | P9: =MIN(E9:H9) -> 140707.54 | Q9: CDE | R9: =MIN(I9:L9) -> 703.53771
C10: Batulicin | D10: 203.111 | E10: =D10/$V$2*6800 -> 345288.7 | F10: =D10/$V$3*6800 -> 197307.83 | G10: =D10/$V$4*10000 -> 253888.75 | H10: =D10/$V$5*10000 -> 203111 | I10: =E10/$T$2 -> 1233.1739 | J10: =F10/$T$3 -> 986.53914 | K10: =G10/$T$4 -> 2115.7396 | L10: =H10/$T$5 -> 2538.8875 | P10: =MIN(E10:H10) -> 197307.83 | Q10: CDE | R10: =MIN(I10:L10) -> 986.53914
C11: Rantau | D11: 94.264 | E11: =D11/$V$2*6800 -> 160248.8 | F11: =D11/$V$3*6800 -> 91570.743 | G11: =D11/$V$4*10000 -> 117830 | H11: =D11/$V$5*10000 -> 94264 | I11: =E11/$T$2 -> 572.31714 | J11: =F11/$T$3 -> 457.85371 | K11: =G11/$T$4 -> 981.91667 | L11: =H11/$T$5 -> 1178.3 | P11: =MIN(E11:H11) -> 91570.743 | Q11: CDE | R11: =MIN(I11:L11) -> 457.85371
A12: Kalimantan | B12: Bontang | C12: Bontang-Sangata | D12: 59.2 | E12: =D12/$V$2*6800 -> 100640 | F12: =D12/$V$3*6800 -> 57508.571 | G12: =D12/$V$4*10000 -> 74000 | H12: =D12/$V$5*10000 -> 59200 | I12: =E12/$T$2 -> 359.42857 | J12: =F12/$T$3 -> 287.54286 | K12: =G12/$T$4 -> 616.66667 | L12: =H12/$T$5 -> 740 | P12: =MIN(E12:H12) -> 57508.571 | Q12: CDE | R12: =MIN(I12:L12) -> 287.54286
A13: Kalimantan | B13: Palangkaraya | C13: Ampah | D13: 343.092 | E13: =D13/$V$2*6800 -> 583256.4 | F13: =D13/$V$3*6800 -> 333289.37 | G13: =D13/$V$4*10000 -> 428865 | H13: =D13/$V$5*10000 -> 343092 | I13: =E13/$T$2 -> 2083.0586 | J13: =F13/$T$3 -> 1666.4469 | K13: =G13/$T$4 -> 3573.875 | L13: =H13/$T$5 -> 4288.65 | P13: =MIN(E13:H13) -> 333289.37 | Q13: CDE | R13: =MIN(I13:L13) -> 1666.4469
A14: Kalimantan | B14: Pontianak | C14: Ketapang | D14: 352.4 | E14: =D14/$V$2*6800 -> 599080 | F14: =D14/$V$3*6800 -> 342331.43 | G14: =D14/$V$4*10000 -> 440500 | H14: =D14/$V$5*10000 -> 352400 | I14: =E14/$T$2 -> 2139.5714 | J14: =F14/$T$3 -> 1711.6571 | K14: =G14/$T$4 -> 3670.8333 | L14: =H14/$T$5 -> 4405 | P14: =MIN(E14:H14) -> 342331.43 | Q14: CDE | R14: =MIN(I14:L14) -> 1711.6571
C15: Singkawang | D15: 151 | E15: =D15/$V$2*6800 -> 256700 | F15: =D15/$V$3*6800 -> 146685.71 | G15: =D15/$V$4*10000 -> 188750 | H15: =D15/$V$5*10000 -> 151000 | I15: =E15/$T$2 -> 916.78571 | J15: =F15/$T$3 -> 733.42857 | K15: =G15/$T$4 -> 1572.9167 | L15: =H15/$T$5 -> 1887.5 | P15: =MIN(E15:H15) -> 146685.71 | Q15: CDE | R15: =MIN(I15:L15) -> 733.42857
C16: Sintang | D16: 321 | E16: =D16/$V$2*6800 -> 545700 | F16: =D16/$V$3*6800 -> 311828.57 | G16: =D16/$V$4*10000 -> 401250 | H16: =D16/$V$5*10000 -> 321000 | I16: =E16/$T$2 -> 1948.9286 | J16: =F16/$T$3 -> 1559.1429 | K16: =G16/$T$4 -> 3343.75 | L16: =H16/$T$5 -> 4012.5 | P16: =MIN(E16:H16) -> 311828.57 | Q16: CDE | R16: =MIN(I16:L16) -> 1559.1429
A17: Kalimantan | B17: Sampit | C17: Pangkalanbun | D17: 212.077 | E17: =$D$4/$V$2*6800 -> 1778868.1 | F17: =$D$4/$V$3*6800 -> 1016496.1 | G17: =$D$4/$V$4*10000 -> 1307991.2 | H17: =$D$4/$V$5*10000 -> 1046393 | I17: =E17/$T$2 -> 6353.1004 | J17: =F17/$T$3 -> 5082.4803 | K17: =G17/$T$4 -> 10899.927 | L17: =H17/$T$5 -> 13079.913 | P17: =MIN(E17:H17) -> 1016496.1 | Q17: CDE | R17: =MIN(I17:L17) -> 5082.4803
A18: Sulawesi | B18: Kendari | C18: Kolaka | D18: 154.22 | E18: =D18/$V$2*6800 -> 262174 | F18: =D18/$V$3*6800 -> 149813.71 | G18: =D18/$V$4*10000 -> 192775 | H18: =D18/$V$5*10000 -> 154220 | I18: =E18/$T$2 -> 936.33571 | J18: =F18/$T$3 -> 749.06857 | K18: =G18/$T$4 -> 1606.4583 | L18: =H18/$T$5 -> 1927.75 | P18: =MIN(E18:H18) -> 149813.71 | Q18: CDE | R18: =MIN(I18:L18) -> 749.06857
C19: Unaaha | D19: 13.78 | E19: =D19/$V$2*6800 -> 23426 | F19: =D19/$V$3*6800 -> 13386.286 | G19: =D19/$V$4*10000 -> 17225 | H19: =D19/$V$5*10000 -> 13780 | I19: =E19/$T$2 -> 83.664286 | J19: =F19/$T$3 -> 66.931429 | K19: =G19/$T$4 -> 143.54167 | L19: =H19/$T$5 -> 172.25 | P19: =MIN(E19:H19) -> 13386.286 | Q19: CDE | R19: =MIN(I19:L19) -> 66.931429
C20: Bau Bau | D20: 275.58 | E20: =D20/$V$2*6800 -> 468486 | F20: =D20/$V$3*6800 -> 267706.29 | G20: =D20/$V$4*10000 -> 344475 | H20: =D20/$V$5*10000 -> 275580 | I20: =E20/$T$2 -> 1673.1643 | J20: =F20/$T$3 -> 1338.5314 | K20: =G20/$T$4 -> 2870.625 | L20: =H20/$T$5 -> 3444.75 | P20: =MIN(E20:H20) -> 267706.29 | Q20: CDE | R20: =MIN(I20:L20) -> 1338.5314
A21: Sulawesi | B21: Manado | C21: Amurang | D21: 55.4 | E21: =D21/$V$2*6800 -> 94180 | F21: =D21/$V$3*6800 -> 53817.143 | G21: =D21/$V$4*10000 -> 69250 | H21: =D21/$V$5*10000 -> 55400 | I21: =E21/$T$2 -> 336.35714 | J21: =F21/$T$3 -> 269.08571 | K21: =G21/$T$4 -> 577.08333 | L21: =H21/$T$5 -> 692.5 | P21: =MIN(E21:H21) -> 53817.143 | Q21: CDE | R21: =MIN(I21:L21) -> 269.08571
C22: Bitung | D22: 47.8 | E22: =D22/$V$2*6800 -> 81260 | F22: =D22/$V$3*6800 -> 46434.286 | G22: =D22/$V$4*10000 -> 59750 | H22: =D22/$V$5*10000 -> 47800 | I22: =E22/$T$2 -> 290.21429 | J22: =F22/$T$3 -> 232.17143 | K22: =G22/$T$4 -> 497.91667 | L22: =H22/$T$5 -> 597.5 | P22: =MIN(E22:H22) -> 46434.286 | Q22: CDE | R22: =MIN(I22:L22) -> 232.17143
C23: Kotamobagu | D23: 170.45 | E23: =D23/$V$2*6800 -> 289765 | F23: =D23/$V$3*6800 -> 165580 | G23: =D23/$V$4*10000 -> 213062.5 | H23: =D23/$V$5*10000 -> 170450 | I23: =E23/$T$2 -> 1034.875 | J23: =F23/$T$3 -> 827.9 | K23: =G23/$T$4 -> 1775.5208 | L23: =H23/$T$5 -> 2130.625 | P23: =MIN(E23:H23) -> 165580 | Q23: CDE | R23: =MIN(I23:L23) -> 827.9
C24: Tomohon | D24: 35.19 | E24: =D24/$V$2*6800 -> 59823 | F24: =D24/$V$3*6800 -> 34184.571 | G24: =D24/$V$4*10000 -> 43987.5 | H24: =D24/$V$5*10000 -> 35190 | I24: =E24/$T$2 -> 213.65357 | J24: =F24/$T$3 -> 170.92286 | K24: =G24/$T$4 -> 366.5625 | L24: =H24/$T$5 -> 439.875 | P24: =MIN(E24:H24) -> 34184.571 | Q24: CDE | R24: =MIN(I24:L24) -> 170.92286
C25: Gorontalo | D25: 396.91 | E25: =D25/$V$2*6800 -> 674747 | F25: =D25/$V$3*6800 -> 385569.71 | G25: =D25/$V$4*10000 -> 496137.5 | H25: =D25/$V$5*10000 -> 396910 | I25: =E25/$T$2 -> 2409.8107 | J25: =F25/$T$3 -> 1927.8486 | K25: =G25/$T$4 -> 4134.4792 | L25: =H25/$T$5 -> 4961.375 | P25: =MIN(E25:H25) -> 385569.71 | Q25: CDE | R25: =MIN(I25:L25) -> 1927.8486
A26: Sulawesi | B26: Makassar | C26: Bulukumba | D26: 200 | E26: =D26/$V$2*6800 -> 340000 | F26: =D26/$V$3*6800 -> 194285.71 | G26: =D26/$V$4*10000 -> 250000 | H26: =D26/$V$5*10000 -> 200000 | I26: =E26/$T$2 -> 1214.2857 | J26: =F26/$T$3 -> 971.42857 | K26: =G26/$T$4 -> 2083.3333 | L26: =H26/$T$5 -> 2500 | P26: =MIN(E26:H26) -> 194285.71 | Q26: CDE | R26: =MIN(I26:L26) -> 971.42857
C27: Gowa | D27: 16.37 | E27: =D27/$V$2*6800 -> 27829 | F27: =D27/$V$3*6800 -> 15902.286 | G27: =D27/$V$4*10000 -> 20462.5 | H27: =D27/$V$5*10000 -> 16370 | I27: =E27/$T$2 -> 99.389286 | J27: =F27/$T$3 -> 79.511429 | K27: =G27/$T$4 -> 170.52083 | L27: =H27/$T$5 -> 204.625 | P27: =MIN(E27:H27) -> 15902.286 | Q27: CDE | R27: =MIN(I27:L27) -> 79.511429
C28: Jeneponto | D28: 97.42 | E28: =D28/$V$2*6800 -> 165614 | F28: =D28/$V$3*6800 -> 94636.571 | G28: =D28/$V$4*10000 -> 121775 | H28: =D28/$V$5*10000 -> 97420 | I28: =E28/$T$2 -> 591.47857 | J28: =F28/$T$3 -> 473.18286 | K28: =G28/$T$4 -> 1014.7917 | L28: =H28/$T$5 -> 1217.75 | P28: =MIN(E28:H28) -> 94636.571 | Q28: CDE | R28: =MIN(I28:L28) -> 473.18286
C29: Pangkep | D29: 55.23 | E29: =D29/$V$2*6800 -> 93891 | F29: =D29/$V$3*6800 -> 53652 | G29: =D29/$V$4*10000 -> 69037.5 | H29: =D29/$V$5*10000 -> 55230 | I29: =E29/$T$2 -> 335.325 | J29: =F29/$T$3 -> 268.26 | K29: =G29/$T$4 -> 575.3125 | L29: =H29/$T$5 -> 690.375 | P29: =MIN(E29:H29) -> 53652 | Q29: CDE | R29: =MIN(I29:L29) -> 268.26
C30: Takalar | D30: 41.33 | E30: =D30/$V$2*6800 -> 70261 | F30: =D30/$V$3*6800 -> 40149.143 | G30: =D30/$V$4*10000 -> 51662.5 | H30: =D30/$V$5*10000 -> 41330 | I30: =E30/$T$2 -> 250.93214 | J30: =F30/$T$3 -> 200.74571 | K30: =G30/$T$4 -> 430.52083 | L30: =H30/$T$5 -> 516.625 | P30: =MIN(E30:H30) -> 40149.143 | Q30: CDE | R30: =MIN(I30:L30) -> 200.74571
C31: Bone | D31: 194.85 | E31: =D31/$V$2*6800 -> 331245 | F31: =D31/$V$3*6800 -> 189282.86 | G31: =D31/$V$4*10000 -> 243562.5 | H31: =D31/$V$5*10000 -> 194850 | I31: =E31/$T$2 -> 1183.0179 | J31: =F31/$T$3 -> 946.41429 | K31: =G31/$T$4 -> 2029.6875 | L31: =H31/$T$5 -> 2435.625 | P31: =MIN(E31:H31) -> 189282.86 | Q31: CDE | R31: =MIN(I31:L31) -> 946.41429
C32: Palopo | D32: 375.38 | E32: =D32/$V$2*6800 -> 638146 | F32: =D32/$V$3*6800 -> 364654.86 | G32: =D32/$V$4*10000 -> 469225 | H32: =D32/$V$5*10000 -> 375380 | I32: =E32/$T$2 -> 2279.0929 | J32: =F32/$T$3 -> 1823.2743 | K32: =G32/$T$4 -> 3910.2083 | L32: =H32/$T$5 -> 4692.25 | P32: =MIN(E32:H32) -> 364654.86 | Q32: CDE | R32: =MIN(I32:L32) -> 1823.2743
C33: Pare-Pare | D33: 162.64 | E33: =D33/$V$2*6800 -> 276488 | F33: =D33/$V$3*6800 -> 157993.14 | G33: =D33/$V$4*10000 -> 203300 | H33: =D33/$V$5*10000 -> 162640 | I33: =E33/$T$2 -> 987.45714 | J33: =F33/$T$3 -> 789.96571 | K33: =G33/$T$4 -> 1694.1667 | L33: =H33/$T$5 -> 2033 | P33: =MIN(E33:H33) -> 157993.14 | Q33: CDE | R33: =MIN(I33:L33) -> 789.96571
C34: Sinjai | D34: 224.38 | E34: =D34/$V$2*6800 -> 381446 | F34: =D34/$V$3*6800 -> 217969.14 | G34: =D34/$V$4*10000 -> 280475 | H34: =D34/$V$5*10000 -> 224380 | I34: =E34/$T$2 -> 1362.3071 | J34: =F34/$T$3 -> 1089.8457 | K34: =G34/$T$4 -> 2337.2917 | L34: =H34/$T$5 -> 2804.75 | P34: =MIN(E34:H34) -> 217969.14 | Q34: CDE | R34: =MIN(I34:L34) -> 1089.8457
A35: Sulawesi | B35: Palu | C35: Parigi | D35: 71.72 | E35: =D35/$V$2*6800 -> 121924 | F35: =D35/$V$3*6800 -> 69670.857 | G35: =D35/$V$4*10000 -> 89650 | H35: =D35/$V$5*10000 -> 71720 | I35: =E35/$T$2 -> 435.44286 | J35: =F35/$T$3 -> 348.35429 | K35: =G35/$T$4 -> 747.08333 | L35: =H35/$T$5 -> 896.5 | P35: =MIN(E35:H35) -> 69670.857 | Q35: CDE | R35: =MIN(I35:L35) -> 348.35429
C36: Luwuk | D36: 589.5 | E36: =D36/$V$2*6800 -> 1002150 | F36: =D36/$V$3*6800 -> 572657.14 | G36: =D36/$V$4*10000 -> 736875 | H36: =D36/$V$5*10000 -> 589500 | I36: =E36/$T$2 -> 3579.1071 | J36: =F36/$T$3 -> 2863.2857 | K36: =G36/$T$4 -> 6140.625 | L36: =H36/$T$5 -> 7368.75 | P36: =MIN(E36:H36) -> 572657.14 | Q36: CDE | R36: =MIN(I36:L36) -> 2863.2857
C37: Mamuju | D37: 406.82 | E37: =D37/$V$2*6800 -> 691594 | F37: =D37/$V$3*6800 -> 395196.57 | G37: =D37/$V$4*10000 -> 508525 | H37: =D37/$V$5*10000 -> 406820 | I37: =E37/$T$2 -> 2469.9786 | J37: =F37/$T$3 -> 1975.9829 | K37: =G37/$T$4 -> 4237.7083 | L37: =H37/$T$5 -> 5085.25 | P37: =MIN(E37:H37) -> 395196.57 | Q37: CDE | R37: =MIN(I37:L37) -> 1975.9829
C38: Poso | D38: 206.67 | E38: =D38/$V$2*6800 -> 351339 | F38: =D38/$V$3*6800 -> 200765.14 | G38: =D38/$V$4*10000 -> 258337.5 | H38: =D38/$V$5*10000 -> 206670 | I38: =E38/$T$2 -> 1254.7821 | J38: =F38/$T$3 -> 1003.8257 | K38: =G38/$T$4 -> 2152.8125 | L38: =H38/$T$5 -> 2583.375 | P38: =MIN(E38:H38) -> 200765.14 | Q38: CDE | R38: =MIN(I38:L38) -> 1003.8257
A39: Sulawesi | B39: Gorontalo | C39: Marissa | D39: 134.66 | E39: =D39/$V$2*6800 -> 228922 | F39: =D39/$V$3*6800 -> 130812.57 | G39: =D39/$V$4*10000 -> 168325 | H39: =D39/$V$5*10000 -> 134660 | I39: =E39/$T$2 -> 817.57857 | J39: =F39/$T$3 -> 654.06286 | K39: =G39/$T$4 -> 1402.7083 | L39: =H39/$T$5 -> 1683.25 | P39: =MIN(E39:H39) -> 130812.57 | Q39: CDE | R39: =MIN(I39:L39) -> 654.06286
A40: Sulawesi | B40: Palopo | C40: Belopa | D40: 49.98 | E40: =D40/$V$2*6800 -> 84966 | F40: =D40/$V$3*6800 -> 48552 | G40: =D40/$V$4*10000 -> 62475 | H40: =D40/$V$5*10000 -> 49980 | I40: =E40/$T$2 -> 303.45 | J40: =F40/$T$3 -> 242.76 | K40: =G40/$T$4 -> 520.625 | L40: =H40/$T$5 -> 624.75 | P40: =MIN(E40:H40) -> 48552 | Q40: CDE | R40: =MIN(I40:L40) -> 242.76
...

Sheet Biaya Penambahan Vehicle
A1: Distributor Area | B1: Area | C1: Type | D1: CDD Cost | E1: CDE Cost | F1: GrandMax Cost | G1: Kijang Cost
A2: Bali Nusra | B2: Denpasar | C2: Direct CPU | D2: 6900000 | E2: 5500000 | F2: 3500000 | I2: motor tidak digunakan karena rate-nya terlalu besar untuk penyewaan saja 1.2 juta, tetapi box yang dikirim tidak sampai 20 box
A3: Bali Nusra | B3: Lombok | C3: Direct CPU | D3: 6900000 | E3: 5500000 | F3: 3500000 | I3: Sewa Motor Bulanan Harian di Bali Kuta Mulai 80 Ribu Per Hari
A4: Bali Nusra | B4: BIMA | C4: Indirect DC | D4: 6900000 | E4: 5500000 | F4: 3500000
A5: Bali Nusra | B5: Kupang | C5: Indirect DC | D5: 6900000 | E5: 5500000 | F5: 3500000
A6: Bali Nusra | B6: Maumere | C6: Indirect DC | D6: 6900000 | E6: 5500000 | F6: 3500000
A7: Bali Nusra | B7: Sumbawa | C7: Indirect DC | D7: 6900000 | E7: 5500000 | F7: 3500000
A8: Kalimantan | B8: Sintang | C8: Depo | D8: 13853970 | E8: 6560843.3 | F8: 6560843.3 | G8: 6560843.3
A9: Kalimantan | B9: Balikpapan | C9: Direct DC | D9: 13853970 | E9: 6560843.3 | F9: 6560843.3 | G9: 6560843.3
A10: Kalimantan | B10: Banjarmasin | C10: Direct DC | D10: 13853970 | E10: 6560843.3 | F10: 6560843.3 | G10: 6560843.3
A11: Kalimantan | B11: Berau | C11: Direct DC | D11: 13853970 | E11: 6560843.3 | F11: 6560843.3 | G11: 6560843.3
A12: Kalimantan | B12: Bontang | C12: Direct DC | D12: 13853970 | E12: 6560843.3 | F12: 6560843.3 | G12: 6560843.3
A13: Kalimantan | B13: Palangkaraya | C13: Direct DC | D13: 13853970 | E13: 6560843.3 | F13: 6560843.3 | G13: 6560843.3
A14: Kalimantan | B14: Pontianak | C14: Direct DC | D14: 13853970 | E14: 6560843.3 | F14: 6560843.3 | G14: 6560843.3
A15: Kalimantan | B15: Samarinda | C15: Direct DC | D15: 13853970 | E15: 6560843.3 | F15: 6560843.3 | G15: 6560843.3
A16: Kalimantan | B16: Sampit | C16: Direct DC | D16: 13853970 | E16: 6560843.3 | F16: 6560843.3 | G16: 6560843.3
A17: Kalimantan | B17: Tarakan | C17: Direct DC | D17: 13853970 | E17: 6560843.3 | F17: 6560843.3 | G17: 6560843.3
A18: Sulawesi | B18: Kendari | C18: Direct CPU | D18: 6900000 | E18: 5500000 | F18: 3500000
A19: Sulawesi | B19: Makassar | C19: Direct CPU | D19: 6900000 | E19: 5500000 | F19: 3500000
A20: Sulawesi | B20: Manado | C20: Direct CPU | D20: 6900000 | E20: 5500000 | F20: 3500000
A21: Sulawesi | B21: Palu | C21: Direct CPU | D21: 6900000 | E21: 5500000 | F21: 3500000
A22: Sulawesi | B22: Bau-Bau | C22: Indirect DC | D22: 6900000 | E22: 5500000 | F22: 3500000
A23: Sulawesi | B23: Bone | C23: Indirect DC | D23: 6900000 | E23: 5500000 | F23: 3500000
A24: Sulawesi | B24: Gorontalo | C24: Indirect DC | D24: 6900000 | E24: 5500000 | F24: 3500000
A25: Sulawesi | B25: Luwuk | C25: Indirect DC | D25: 6900000 | E25: 5500000 | F25: 3500000
A26: Sulawesi | B26: Mamuju | C26: Indirect DC | D26: 6900000 | E26: 5500000 | F26: 3500000
A27: Sulawesi | B27: Palopo | C27: Indirect DC | D27: 6900000 | E27: 5500000 | F27: 3500000
A28: Sulawesi | B28: Pare-Pare | C28: Indirect DC | D28: 6900000 | E28: 5500000 | F28: 3500000
A29: Sulawesi | B29: Poso | C29: Indirect DC | D29: 6900000 | E29: 5500000 | F29: 3500000

Sheet Jumlah Trip Maksimal
A1: 🧑‍💼 HUMAN-CENTRIC CONSTRAINT — Trip Maksimum Kendaraan per Lokasi Asal
A2: Formula: T_k = FLOOR( JamKerja_PerBulan / (Jarak_Terjauh / Kecepatan) , 1)
A3: Implementasi: D = Jarak/Kecepatan (waktu trip 1 arah, jam) · E = FLOOR(JamKerja_PerBulan/D, 1) · F = JamKerja_PerBulan · G = cek E×D≤F
A5: Distributor Area | B5: Area | C5: Type | D5: Waktu TRIP(jarak terjauh dibagi 45 km/hour) | E5: MaxTrip | F5: Waktu Tersedia | G5: Total waktu<waktu tersedia | K5: DC ID | L5: Area | M5: Type | N5: Capacity Kendaraan | O5: Waktu Trip Terjauh | P5: Maximum Trip | Q5: Waktu Tersedia
A6: Bali Nusra | B6: Denpasar | C6: Direct CPU | E6: =IFERROR(FLOOR(F6/D6,1),"-") -> - | F6: =JamKerja_PerBulan -> 208 | G6: =IFERROR(IF(E6*D6<F6,TRUE()),"-") -> - | I6: Jumlah Paket Trip | K6: DC031 | L6: Denpasar | M6: Direct CPU | N6: 5280 | O6: - | P6: - | Q6: =JamKerja_PerBulan -> 208
A7: Bali Nusra | B7: Lombok | C7: Direct CPU | D7: =1046.393/Kecepatan_Kendaraan -> 23.253178 | E7: =IFERROR(FLOOR(F7/D7,1),"-") -> 8 | F7: =JamKerja_PerBulan -> 208 | G7: =IFERROR(IF(E7*D7<F7,TRUE()),"-") -> TRUE | I7: =COUNT(D3,D9,D10,D12,D13,D14,D16,D18,D19,D20,D21,D24,D27,D28) -> 7 | K7: DC032 | L7: Kendari | M7: Direct CPU | N7: 1640 | O7: =275.58/Kecepatan_Kendaraan -> 6.124 | P7: =IFERROR(FLOOR(Q7/O7,1),"-") -> 33 | Q7: =JamKerja_PerBulan -> 208
A8: Bali Nusra | B8: BIMA | C8: Indirect DC | E8: =IFERROR(FLOOR(F8/D8,1),"-") -> - | F8: =JamKerja_PerBulan -> 208 | G8: =IFERROR(IF(E8*D8<F8,TRUE()),"-") -> - | K8: DC033 | L8: Lombok | M8: Direct CPU | N8: 1600 | O8: =1046.393/Kecepatan_Kendaraan -> 23.253178 | P8: 8 | Q8: =JamKerja_PerBulan -> 208
A9: Bali Nusra | B9: Kupang | C9: Indirect DC | E9: =IFERROR(FLOOR(F9/D9,1),"-") -> - | F9: =JamKerja_PerBulan -> 208 | G9: =IFERROR(IF(E9*D9<F9,TRUE()),"-") -> - | K9: DC034 | L9: Makassar | M9: Direct CPU | N9: 2920 | O9: =357.38/Kecepatan_Kendaraan -> 7.9417778 | P9: 26 | Q9: =JamKerja_PerBulan -> 208
A10: Bali Nusra | B10: Maumere | C10: Indirect DC | E10: =IFERROR(FLOOR(F10/D10,1),"-") -> - | F10: =JamKerja_PerBulan -> 208 | G10: =IFERROR(IF(E10*D10<F10,TRUE()),"-") -> - | K10: DC035 | L10: Manado | M10: Direct CPU | N10: 3400 | O10: =396.91/Kecepatan_Kendaraan -> 8.8202222 | P10: =IFERROR(FLOOR(Q10/O10,1),"-") -> 23 | Q10: =JamKerja_PerBulan -> 208
A11: Bali Nusra | B11: Sumbawa | C11: Indirect DC | E11: =IFERROR(FLOOR(F11/D11,1),"-") -> - | F11: =JamKerja_PerBulan -> 208 | G11: =IFERROR(IF(E11*D11<F11,TRUE()),"-") -> - | K11: DC036 | L11: Palu | M11: Direct CPU | N11: 1560 | O11: =589.5/Kecepatan_Kendaraan -> 13.1 | P11: =IFERROR(FLOOR(Q11/O11,1),"-") -> 15 | Q11: =JamKerja_PerBulan -> 208
A12: Kalimantan | B12: Sintang | C12: Depo | E12: =IFERROR(FLOOR(F12/D12,1),"-") -> - | F12: =JamKerja_PerBulan -> 208 | G12: =IFERROR(IF(E12*D12<F12,TRUE()),"-") -> - | K12: DC037 | L12: Balikpapan | M12: Direct DC | N12: 2880 | O12: =161.958/Kecepatan_Kendaraan -> 3.5990667 | P12: =IFERROR(FLOOR(Q12/O12,1),"-") -> 57 | Q12: =JamKerja_PerBulan -> 208
A13: Kalimantan | B13: Balikpapan | C13: Direct DC | D13: =161.958/Kecepatan_Kendaraan -> 3.5990667 | E13: =IFERROR(FLOOR(F13/D13,1),"-") -> 57 | F13: =JamKerja_PerBulan -> 208 | G13: =IFERROR(IF(E13*D13<F13,TRUE()),"-") -> TRUE | K13: DC038 | L13: Banjarmasin | M13: Direct DC | N13: 5280 | O13: =203.111/Kecepatan_Kendaraan -> 4.5135778 | P13: =IFERROR(FLOOR(Q13/O13,1),"-") -> 46 | Q13: =JamKerja_PerBulan -> 208
A14: Kalimantan | B14: Banjarmasin | C14: Direct DC | D14: =203.111/Kecepatan_Kendaraan -> 4.5135778 | E14: =IFERROR(FLOOR(F14/D14,1),"-") -> 46 | F14: =JamKerja_PerBulan -> 208 | G14: =IFERROR(IF(E14*D14<F14,TRUE()),"-") -> TRUE | K14: DC039 | L14: Berau | M14: Direct DC | N14: 520 | O14: - | P14: - | Q14: =JamKerja_PerBulan -> 208
A15: Kalimantan | B15: Berau | C15: Direct DC | E15: =IFERROR(FLOOR(F15/D15,1),"-") -> - | F15: =JamKerja_PerBulan -> 208 | G15: =IFERROR(IF(E15*D15<F15,TRUE()),"-") -> - | K15: DC040 | L15: Bontang | M15: Direct DC | N15: 5280 | O15: =59.2/Kecepatan_Kendaraan -> 1.3155556 | P15: =IFERROR(FLOOR(Q15/O15,1),"-") -> 158 | Q15: =JamKerja_PerBulan -> 208
A16: Kalimantan | B16: Bontang | C16: Direct DC | D16: =59.2/Kecepatan_Kendaraan -> 1.3155556 | E16: =IFERROR(FLOOR(F16/D16,1),"-") -> 158 | F16: =JamKerja_PerBulan -> 208 | G16: =IFERROR(IF(E16*D16<F16,TRUE()),"-") -> TRUE | K16: DC041 | L16: Palangkaraya | M16: Direct DC | N16: 1040 | O16: =343.092/Kecepatan_Kendaraan -> 7.6242667 | P16: =IFERROR(FLOOR(Q16/O16,1),"-") -> 27 | Q16: =JamKerja_PerBulan -> 208
A17: Kalimantan | B17: Palangkaraya | C17: Direct DC | D17: =343.092/Kecepatan_Kendaraan -> 7.6242667 | E17: =IFERROR(FLOOR(F17/D17,1),"-") -> 27 | F17: =JamKerja_PerBulan -> 208 | G17: =IFERROR(IF(E17*D17<F17,TRUE()),"-") -> TRUE | K17: DC042 | L17: Pontianak | M17: Direct DC | N17: 5280 | O17: =352.4/Kecepatan_Kendaraan -> 7.8311111 | P17: =IFERROR(FLOOR(Q17/O17,1),"-") -> 26 | Q17: =JamKerja_PerBulan -> 208
A18: Kalimantan | B18: Pontianak | C18: Direct DC | D18: =352.4/Kecepatan_Kendaraan -> 7.8311111 | E18: =IFERROR(FLOOR(F18/D18,1),"-") -> 26 | F18: =JamKerja_PerBulan -> 208 | G18: =IFERROR(IF(E18*D18<F18,TRUE()),"-") -> TRUE | K18: DC043 | L18: Samarinda | M18: Direct DC | N18: 1800 | O18: - | P18: - | Q18: =JamKerja_PerBulan -> 208
A19: Kalimantan | B19: Samarinda | C19: Direct DC | E19: =IFERROR(FLOOR(F19/D19,1),"-") -> - | F19: =JamKerja_PerBulan -> 208 | G19: =IFERROR(IF(E19*D19<F19,TRUE()),"-") -> - | K19: DC044 | L19: Sampit | M19: Direct DC | N19: 1000 | O19: =212.077/Kecepatan_Kendaraan -> 4.7128222 | P19: =IFERROR(FLOOR(Q19/O19,1),"-") -> 44 | Q19: =JamKerja_PerBulan -> 208
A20: Kalimantan | B20: Sampit | C20: Direct DC | D20: =212.077/Kecepatan_Kendaraan -> 4.7128222 | E20: =IFERROR(FLOOR(F20/D20,1),"-") -> 44 | F20: =JamKerja_PerBulan -> 208 | G20: =IFERROR(IF(E20*D20<F20,TRUE()),"-") -> TRUE | K20: DC045 | L20: Tarakan | M20: Direct DC | N20: 520 | O20: - | P20: - | Q20: =JamKerja_PerBulan -> 208
A21: Kalimantan | B21: Tarakan | C21: Direct DC | E21: =IFERROR(FLOOR(F21/D21,1),"-") -> - | F21: =JamKerja_PerBulan -> 208 | G21: =IFERROR(IF(E21*D21<F21,TRUE()),"-") -> - | K21: DC046 | L21: Bau-Bau | M21: Indirect DC | N21: 200 | O21: - | P21: - | Q21: =JamKerja_PerBulan -> 208
A22: Sulawesi | B22: Kendari | C22: Direct CPU | D22: =275.58/Kecepatan_Kendaraan -> 6.124 | E22: =IFERROR(FLOOR(F22/D22,1),"-") -> 33 | F22: =JamKerja_PerBulan -> 208 | G22: =IFERROR(IF(E22*D22<F22,TRUE()),"-") -> TRUE | K22: DC047 | L22: BIMA | M22: Indirect DC | N22: 400 | O22: - | P22: - | Q22: =JamKerja_PerBulan -> 208
A23: Sulawesi | B23: Makassar | C23: Direct CPU | D23: =357.38/Kecepatan_Kendaraan -> 7.9417778 | E23: 26 | F23: =JamKerja_PerBulan -> 208 | G23: =IFERROR(IF(E23*D23<F23,TRUE()),"-") -> TRUE | K23: DC048 | L23: Bone | M23: Indirect DC | N23: 600 | O23: - | P23: - | Q23: =JamKerja_PerBulan -> 208
A24: Sulawesi | B24: Manado | C24: Direct CPU | D24: =396.91/Kecepatan_Kendaraan -> 8.8202222 | E24: =IFERROR(FLOOR(F24/D24,1),"-") -> 23 | F24: =JamKerja_PerBulan -> 208 | G24: =IFERROR(IF(E24*D24<F24,TRUE()),"-") -> TRUE | K24: DC049 | L24: Gorontalo | M24: Indirect DC | N24: 1120 | O24: =134.66/Kecepatan_Kendaraan -> 2.9924444 | P24: =IFERROR(FLOOR(Q24/O24,1),"-") -> 69 | Q24: =JamKerja_PerBulan -> 208
A25: Sulawesi | B25: Palu | C25: Direct CPU | D25: =589.5/Kecepatan_Kendaraan -> 13.1 | E25: =IFERROR(FLOOR(F25/D25,1),"-") -> 15 | F25: =JamKerja_PerBulan -> 208 | G25: =IFERROR(IF(E25*D25<F25,TRUE()),"-") -> TRUE | K25: DC050 | L25: Kupang | M25: Indirect DC | N25: 1240 | O25: - | P25: - | Q25: =JamKerja_PerBulan -> 208
A26: Sulawesi | B26: Bau-Bau | C26: Indirect DC | E26: =IFERROR(FLOOR(F26/D26,1),"-") -> - | F26: =JamKerja_PerBulan -> 208 | G26: =IFERROR(IF(E26*D26<F26,TRUE()),"-") -> - | K26: DC051 | L26: Luwuk | M26: Indirect DC | N26: 320 | O26: - | P26: - | Q26: =JamKerja_PerBulan -> 208
A27: Sulawesi | B27: Bone | C27: Indirect DC | E27: =IFERROR(FLOOR(F27/D27,1),"-") -> - | F27: =JamKerja_PerBulan -> 208 | G27: =IFERROR(IF(E27*D27<F27,TRUE()),"-") -> - | K27: DC052 | L27: Mamuju | M27: Indirect DC | N27: 400 | O27: - | P27: - | Q27: =JamKerja_PerBulan -> 208
A28: Sulawesi | B28: Gorontalo | C28: Indirect DC | D28: =134.66/Kecepatan_Kendaraan -> 2.9924444 | E28: =IFERROR(FLOOR(F28/D28,1),"-") -> 69 | F28: =JamKerja_PerBulan -> 208 | G28: =IFERROR(IF(E28*D28<F28,TRUE()),"-") -> TRUE | K28: DC053 | L28: Maumere | M28: Indirect DC | N28: 960 | O28: - | P28: - | Q28: =JamKerja_PerBulan -> 208
A29: Sulawesi | B29: Luwuk | C29: Indirect DC | E29: =IFERROR(FLOOR(F29/D29,1),"-") -> - | F29: =JamKerja_PerBulan -> 208 | G29: =IFERROR(IF(E29*D29<F29,TRUE()),"-") -> - | K29: DC054 | L29: Palopo | M29: Indirect DC | N29: 1640 | O29: =138.45/Kecepatan_Kendaraan -> 3.0766667 | P29: =IFERROR(FLOOR(Q29/O29,1),"-") -> 67 | Q29: =JamKerja_PerBulan -> 208
A30: Sulawesi | B30: Mamuju | C30: Indirect DC | E30: =IFERROR(FLOOR(F30/D30,1),"-") -> - | F30: =JamKerja_PerBulan -> 208 | G30: =IFERROR(IF(E30*D30<F30,TRUE()),"-") -> - | K30: DC055 | L30: Pare-Pare | M30: Indirect DC | N30: 1480 | O30: =103.54/Kecepatan_Kendaraan -> 2.3008889 | P30: =IFERROR(FLOOR(Q30/O30,1),"-") -> 90 | Q30: =JamKerja_PerBulan -> 208
A31: Sulawesi | B31: Palopo | C31: Indirect DC | D31: =138.45/Kecepatan_Kendaraan -> 3.0766667 | E31: =IFERROR(FLOOR(F31/D31,1),"-") -> 67 | F31: =JamKerja_PerBulan -> 208 | G31: =IFERROR(IF(E31*D31<F31,TRUE()),"-") -> TRUE | K31: DC056 | L31: Poso | M31: Indirect DC | N31: 800 | O31: - | P31: - | Q31: =JamKerja_PerBulan -> 208
A32: Sulawesi | B32: Pare-Pare | C32: Indirect DC | D32: =103.54/Kecepatan_Kendaraan -> 2.3008889 | E32: =IFERROR(FLOOR(F32/D32,1),"-") -> 90 | F32: =JamKerja_PerBulan -> 208 | G32: =IFERROR(IF(E32*D32<F32,TRUE()),"-") -> TRUE | K32: DC057 | L32: Sumbawa | M32: Indirect DC | N32: 320 | O32: - | P32: - | Q32: =JamKerja_PerBulan -> 208
A33: Sulawesi | B33: Poso | C33: Indirect DC | E33: =IFERROR(FLOOR(F33/D33,1),"-") -> - | F33: =JamKerja_PerBulan -> 208 | G33: =IFERROR(IF(E33*D33<F33,TRUE()),"-") -> - | Q33: =JamKerja_PerBulan -> 208

Sheet (SRP Usulan) Jarak Tempuh Middl
A1: ID Asal | B1: Nama Kota | C1: Id Tujuan | D1: Nama Kota Tujuan | E1: Jarak(KM)
A2: DC037 | B2: Balikpapan | C2: DC020 | D2: Penajam-Grogot | E2: 161.958 | F2: =E2*2 -> 323.916 | G2: =F2/45 -> 7.1981333 | H2: =ROUNDUP(G2/(8*30),0) -> 1 | I2: =G2/L2 -> 0.044988333 | J2: =ROUNDUP(I2/L3,0) -> 1 | K2: jam kerja= | L2: 160 | N2: ID Asal | O2: Nama Kota | P2: Id Tujuan | Q2: Nama Kota Tujuan | R2: Jarak(KM) | T2: ID Asal | U2: Lokasi Asal | V2: ID Tujuan | W2: Nama Kota | X2: Jarak (km)
A3: DC038 | B3: Banjarmasin | C3: DC003 | D3: Barabai | E3: 144.846 | F3: =E3*2 -> 289.692 | G3: =F3/45 -> 6.4376 | H3: =ROUNDUP(G3/(8*30),0) -> 1 | K3: trip/bulan | L3: 10 | N3: DC041 | O3: Palangkaraya | P3: DC001 | Q3: Ampah - Teweh | R3: 343.092 | T3: DC037 | U3: Balikpapan | V3: DC020 | W3: Penajam-Grogot | X3: 161.958
A4: DC038 | B4: Banjarmasin | C4: DC005 | D4: Batulicin | E4: 203.111 | F4: =E4*2 -> 406.222 | G4: =F4/45 -> 9.0271556 | H4: =ROUNDUP(G4/(8*30),0) -> 1 | N4: DC035 | O4: Manado | P4: DC002 | Q4: Amurang | R4: 55.4 | T4: DC038 | U4: Banjarmasin | V4: DC003 | W4: Barabai | X4: 144.846
A5: DC038 | B5: Banjarmasin | C5: DC022 | D5: Rantau | E5: 94.264 | F5: =E5*2 -> 188.528 | G5: =F5/45 -> 4.1895111 | H5: =ROUNDUP(G5/(8*30),0) -> 1 | N5: DC038 | O5: Banjarmasin | P5: DC003 | Q5: Barabai | R5: 144.846 | T5: DC038 | U5: Banjarmasin | V5: DC005 | W5: Batulicin | X5: 203.111
A6: DC040 | B6: Bontang | C6: DC008 | D6: Bontang-Sangata | E6: 59.2 | F6: =E6*2 -> 118.4 | G6: =F6/45 -> 2.6311111 | H6: =ROUNDUP(G6/(8*30),0) -> 1 | N6: DC055 | O6: Pare-Pare | P6: DC004 | Q6: Barru | R6: 62.41 | T6: DC038 | U6: Banjarmasin | V6: DC022 | W6: Rantau | X6: 94.264
A7: DC049 | B7: Gorontalo | C7: DC016 | D7: Marisa | E7: 134.66 | F7: =E7*2 -> 269.32 | G7: =F7/45 -> 5.9848889 | H7: =ROUNDUP(G7/(8*30),0) -> 1 | N7: DC038 | O7: Banjarmasin | P7: DC005 | Q7: Batulicin | R7: 203.111 | T7: DC040 | U7: Bontang | V7: DC008 | W7: Bontang-Sangata | X7: 59.2
A8: DC032 | B8: Kendari | C8: DC013 | D8: Kolaka | E8: 154.22 | N8: DC054 | O8: Palopo | P8: DC006 | Q8: Belopa | R8: 49.98 | T8: DC033 | U8: Lombok | V8: DC047 | W8: BIMA | X8: 440.971
A9: DC032 | B9: Kendari | C9: DC030 | D9: Unaaha | E9: 13.78 | N9: DC035 | O9: Manado | P9: DC007 | Q9: Bitung | R9: 47.8 | T9: DC049 | U9: Gorontalo | V9: DC016 | W9: Marisa | X9: 134.66
A10: DC032 | B10: Kendari | C10: DC046 | D10: Bau-Bau | E10: 275.58 | N10: DC040 | O10: Bontang | P10: DC008 | Q10: Bontang-Sangata | R10: 59.2 | T10: PabrikKarawang | U10: Karawang | V10: DC031 | W10: Denpasar | X10: 1044.466
A11: DC033 | B11: Lombok | C11: DC047 | D11: BIMA | E11: 440.971 | F11: =COUNT(Table1[Jarak(KM)]) -> 42 | N11: DC034 | O11: Makassar | P11: DC009 | Q11: Bulukumba | R11: 200 | T11: PabrikKarawang | U11: Karawang | V11: DC033 | W11: Lombok | X11: 1144.628
A12: DC033 | B12: Lombok | C12: DC050 | D12: Kupang | E12: 1046.393 | N12: DC034 | O12: Makassar | P12: DC010 | Q12: Gowa | R12: 16.37 | T12: DC032 | U12: Kendari | V12: DC046 | W12: Bau-Bau | X12: 275.58
A13: DC033 | B13: Lombok | C13: DC053 | D13: Maumere | E13: 924.619 | N13: DC034 | O13: Makassar | P13: DC011 | Q13: Jeneponto | R13: 97.42 | T13: DC032 | U13: Kendari | V13: DC013 | W13: Kolaka | X13: 154.22
A14: DC033 | B14: Lombok | C14: DC057 | D14: Sumbawa | E14: 179.485 | N14: DC042 | O14: Pontianak | P14: DC012 | Q14: Ketapang | R14: 352.4 | T14: DC032 | U14: Kendari | V14: DC030 | W14: Unaaha | X14: 13.78
A15: DC034 | B15: Makassar | C15: DC009 | D15: Bulukumba | E15: 200 | N15: DC032 | O15: Kendari | P15: DC013 | Q15: Kolaka | R15: 154.22 | T15: DC033 | U15: Lombok | V15: DC050 | W15: Kupang | X15: 1046.393
A16: DC034 | B16: Makassar | C16: DC010 | D16: Gowa | E16: 16.37 | N16: DC035 | O16: Manado | P16: DC014 | Q16: Kotamobagu | R16: 170.45 | T16: DC033 | U16: Lombok | V16: DC053 | W16: Maumere | X16: 924.619
A17: DC034 | B17: Makassar | C17: DC011 | D17: Jeneponto | E17: 97.42 | N17: DC054 | O17: Palopo | P17: DC015 | Q17: Mangkutana | R17: 138.45 | T17: DC033 | U17: Lombok | V17: DC057 | W17: Sumbawa | X17: 179.485
A18: DC034 | B18: Makassar | C18: DC018 | D18: Pangkep | E18: 55.23 | N18: DC049 | O18: Gorontalo | P18: DC016 | Q18: Marisa | R18: 134.66 | T18: DC034 | U18: Makassar | V18: DC048 | W18: Bone | X18: 194.85
A19: DC034 | B19: Makassar | C19: DC025 | D19: Sinjai | E19: 224.38 | N19: DC044 | O19: Sampit | P19: DC017 | Q19: Pangkalanbun | R19: 212.077 | T19: DC034 | U19: Makassar | V19: DC009 | W19: Bulukumba | X19: 200
A20: DC034 | B20: Makassar | C20: DC027 | D20: Takalar | E20: 41.33 | N20: DC034 | O20: Makassar | P20: DC018 | Q20: Pangkep | R20: 55.23 | T20: DC034 | U20: Makassar | V20: DC010 | W20: Gowa | X20: 16.37
A21: DC034 | B21: Makassar | C21: DC048 | D21: Bone | E21: 194.85 | N21: DC036 | O21: Palu | P21: DC019 | Q21: Parigi | R21: 71.72 | T21: DC034 | U21: Makassar | V21: DC011 | W21: Jeneponto | X21: 97.42
A22: DC034 | B22: Makassar | C22: DC054 | D22: Palopo | E22: 375.38 | N22: DC037 | O22: Balikpapan | P22: DC020 | Q22: Penajam-Grogot | R22: 161.958 | T22: DC034 | U22: Makassar | V22: DC054 | W22: Palopo | X22: 375.38
A23: DC034 | B23: Makassar | C23: DC055 | D23: Pare-Pare | E23: 162.64 | N23: DC055 | O23: Pare-Pare | P23: DC021 | Q23: Polman | R23: 103.54 | T23: DC034 | U23: Makassar | V23: DC018 | W23: Pangkep | X23: 55.23
... A31: DC054 | B31: Palopo | C31: DC015 | D31: Mangkutana | E31: 138.45 | N31: DC054 | O31: Palopo | P31: DC029 | Q31: Toraja | R31: 72.18 | T31: DC054 | U31: Palopo | V31: DC006 | W31: Belopa | X31: 49.98
A32: DC054 | B32: Palopo | C32: DC029 | D32: Toraja | E32: 72.18 | H32: PabrikKarawang | I32: Karawang | J32: DC031 | K32: Denpasar | L32: 1044.466 | N32: DC032 | O32: Kendari | P32: DC030 | Q32: Unaaha | R32: 13.78 | T32: DC054 | U32: Palopo | V32: DC029 | W32: Toraja | X32: 72.18
A33: DC036 | B33: Palu | C33: DC019 | D33: Parigi | E33: 71.72 | H33: PabrikKarawang | I33: Karawang | J33: DC034 | K33: Lombok | L33: 1144.628 | N33: DC032 | O33: Kendari | P33: DC046 | Q33: Bau-Bau | R33: 275.58 | T33: DC054 | U33: Palopo | V33: DC015 | W33: Mangkutana | X33: 138.45
A34: DC036 | B34: Palu | C34: DC051 | D34: Luwuk | E34: 589.5 | N34: DC034 | O34: Makassar | P34: DC055 | Q34: Pare-Pare | R34: 162.64 | T34: DC036 | U34: Palu | V34: DC051 | W34: Luwuk | X34: 589.5
A35: DC036 | B35: Palu | C35: DC052 | D35: Mamuju | E35: 406.82 | N35: DC033 | O35: Lombok | P35: DC047 | Q35: BIMA | R35: 440.971 | T35: DC036 | U35: Palu | V35: DC052 | W35: Mamuju | X35: 406.82
A36: DC036 | B36: Palu | C36: DC056 | D36: Poso | E36: 206.67 | N36: DC034 | O36: Makassar | P36: DC048 | Q36: Bone | R36: 194.85 | T36: DC036 | U36: Palu | V36: DC019 | W36: Parigi | X36: 71.72
A37: DC055 | B37: Pare-Pare | C37: DC004 | D37: Barru | E37: 62.41 | N37: DC035 | O37: Manado | P37: DC049 | Q37: Gorontalo | R37: 396.91 | T37: DC036 | U37: Palu | V37: DC056 | W37: Poso | X37: 206.67
